'use client';

import React, { Component, ReactNode } from 'react';
import { AlertTriangle, RefreshCw, Home } from 'lucide-react';

interface Props {
  children: ReactNode;
  fallback?: ReactNode;
  onError?: (error: Error, errorInfo: React.ErrorInfo) => void;
}

interface State {
  hasError: boolean;
  error: Error | null;
  errorInfo: React.ErrorInfo | null;
  retryCount: number;
}

class ErrorBoundary extends Component<Props, State> {
  private retryTimeouts: NodeJS.Timeout[] = [];

  constructor(props: Props) {
    super(props);
    this.state = {
      hasError: false,
      error: null,
      errorInfo: null,
      retryCount: 0,
    };
  }

  static getDerivedStateFromError(error: Error): Partial<State> {
    return {
      hasError: true,
      error,
    };
  }

  componentDidCatch(error: Error, errorInfo: React.ErrorInfo) {
    // Log error to monitoring service
    console.error('ErrorBoundary caught an error:', error, errorInfo);

    // Call custom error handler if provided
    if (this.props.onError) {
      this.props.onError(error, errorInfo);
    }

    // Send to analytics/monitoring service
    if (typeof window !== 'undefined' && window.gtag) {
      window.gtag('event', 'exception', {
        description: error.message,
        fatal: false,
      });
    }

    this.setState({
      errorInfo,
    });
  }

  componentWillUnmount() {
    // Clear any pending retry timeouts
    this.retryTimeouts.forEach(timeout => clearTimeout(timeout));
  }

  handleRetry = () => {
    const { retryCount } = this.state;
    const maxRetries = 3;

    if (retryCount < maxRetries) {
      // Exponential backoff: 1s, 2s, 4s
      const delay = Math.pow(2, retryCount) * 1000;

      const timeout = setTimeout(() => {
        this.setState({
          hasError: false,
          error: null,
          errorInfo: null,
          retryCount: retryCount + 1,
        });
      }, delay);

      this.retryTimeouts.push(timeout);
    }
  };

  handleReset = () => {
    this.setState({
      hasError: false,
      error: null,
      errorInfo: null,
      retryCount: 0,
    });
  };

  render() {
    if (this.state.hasError) {
      // Custom fallback UI
      if (this.props.fallback) {
        return this.props.fallback;
      }

      // Default error UI
      return (
        <div className="min-h-[400px] flex items-center justify-center p-6">
          <div className="max-w-md w-full bg-white rounded-xl shadow-lg border border-red-200 p-6">
            <div className="flex items-center justify-center mb-4">
              <div className="bg-red-100 rounded-full p-3">
                <AlertTriangle className="h-8 w-8 text-red-600" />
              </div>
            </div>

            <div className="text-center mb-6">
              <h2 className="text-xl font-semibold text-gray-900 mb-2">
                Something went wrong
              </h2>
              <p className="text-gray-600 text-sm mb-4">
                We encountered an unexpected error. This has been reported to our team.
              </p>

              {process.env.NODE_ENV === 'development' && this.state.error && (
                <details className="text-left bg-gray-50 p-3 rounded-lg mb-4">
                  <summary className="cursor-pointer text-sm font-medium text-gray-700 mb-2">
                    Error Details (Development Only)
                  </summary>
                  <pre className="text-xs text-red-600 whitespace-pre-wrap overflow-auto max-h-32">
                    {this.state.error.message}
                    {this.state.errorInfo?.componentStack}
                  </pre>
                </details>
              )}
            </div>

            <div className="flex flex-col sm:flex-row gap-3">
              <button
                onClick={this.handleRetry}
                disabled={this.state.retryCount >= 3}
                className="flex-1 flex items-center justify-center px-4 py-2 bg-blue-600 text-white rounded-lg hover:bg-blue-700 disabled:bg-gray-400 disabled:cursor-not-allowed transition-colors"
              >
                <RefreshCw className="h-4 w-4 mr-2" />
                {this.state.retryCount >= 3 ? 'Max retries reached' : 'Try Again'}
              </button>

              <button
                onClick={this.handleReset}
                className="flex-1 flex items-center justify-center px-4 py-2 bg-gray-200 text-gray-700 rounded-lg hover:bg-gray-300 transition-colors"
              >
                <Home className="h-4 w-4 mr-2" />
                Reset
              </button>
            </div>

            <div className="mt-4 text-center">
              <button
                onClick={() => window.location.reload()}
                className="text-sm text-gray-500 hover:text-gray-700 underline"
              >
                Or refresh the page
              </button>
            </div>
          </div>
        </div>
      );
    }

    return this.props.children;
  }
}

// Hook for using error boundary in functional components
export const useErrorHandler = () => {
  return (error: Error, errorInfo?: { componentStack?: string }) => {
    console.error('Error handled by hook:', error, errorInfo);

    // Send to monitoring service
    if (typeof window !== 'undefined' && window.gtag) {
      window.gtag('event', 'exception', {
        description: error.message,
        fatal: false,
      });
    }
  };
};

// Higher-order component for wrapping components with error boundary
export const withErrorBoundary = <P extends object>(
  Component: React.ComponentType<P>,
  errorBoundaryProps?: Omit<Props, 'children'>
) => {
  const WrappedComponent = (props: P) => (
    <ErrorBoundary {...errorBoundaryProps}>
      <Component {...props} />
    </ErrorBoundary>
  );

  WrappedComponent.displayName = `withErrorBoundary(${Component.displayName || Component.name})`;

  return WrappedComponent;
};

export default ErrorBoundary;
